Workbook
Name XData: 経路!$H$2:INDEX(経路!$H:$H,経路!$G$11)
Name YData: 経路!$I$2:INDEX(経路!$I:$I,経路!$G$11)

Sheet ログ
A1: start
A2: 13 | B2: 5 | C2: 5 | D2: 3 | E2: 9 | F2: 1 | G2: 1 | H2: 1 | I2: 1 | J2: 1 | K2: 1 | L2: 1 | M2: 1 | N2: 1 | O2: 1 | P2: 3
A3: 11 | B3: 9 | C3: 5 | D3: 2 | E3: 8 | F3: 0 | G3: 0 | H3: 0 | I3: 0 | J3: 0 | K3: 0 | L3: 0 | M3: 0 | N3: 0 | O3: 0 | P3: 2
A4: 10 | B4: 10 | C4: 11 | D4: 12 | E4: 0 | F4: 0 | G4: 0 | H4: 0 | I4: 0 | J4: 0 | K4: 0 | L4: 0 | M4: 0 | N4: 0 | O4: 0 | P4: 2
A5: 10 | B5: 12 | C5: 4 | D5: 3 | E5: 8 | F5: 0 | G5: 0 | H5: 0 | I5: 0 | J5: 0 | K5: 0 | L5: 0 | M5: 0 | N5: 0 | O5: 0 | P5: 2
A6: 8 | B6: 3 | C6: 9 | D6: 2 | E6: 8 | F6: 0 | G6: 0 | H6: 0 | I6: 0 | J6: 0 | K6: 0 | L6: 0 | M6: 0 | N6: 0 | O6: 0 | P6: 2
A7: 10 | B7: 14 | C7: 14 | D7: 10 | E7: 8 | F7: 0 | G7: 0 | H7: 0 | I7: 0 | J7: 0 | K7: 0 | L7: 0 | M7: 0 | N7: 0 | O7: 0 | P7: 2
A8: 10 | B8: 11 | C8: 11 | D8: 10 | E8: 8 | F8: 0 | G8: 0 | H8: 0 | I8: 0 | J8: 0 | K8: 0 | L8: 0 | M8: 0 | N8: 0 | O8: 0 | P8: 2
A9: 12 | B9: 4 | C9: 4 | D9: 6 | E9: 8 | F9: 0 | G9: 0 | H9: 0 | I9: 0 | J9: 0 | K9: 0 | L9: 0 | M9: 0 | N9: 0 | O9: 0 | P9: 2
A10: 9 | B10: 1 | C10: 1 | D10: 1 | E10: 0 | F10: 0 | G10: 0 | H10: 0 | I10: 0 | J10: 0 | K10: 0 | L10: 0 | M10: 0 | N10: 0 | O10: 0 | P10: 2
A11: 8 | B11: 0 | C11: 0 | D11: 0 | E11: 0 | F11: 0 | G11: 0 | H11: 0 | I11: 0 | J11: 0 | K11: 0 | L11: 0 | M11: 0 | N11: 0 | O11: 0 | P11: 2
A12: 8 | B12: 0 | C12: 0 | D12: 0 | E12: 0 | F12: 0 | G12: 0 | H12: 0 | I12: 0 | J12: 0 | K12: 0 | L12: 0 | M12: 0 | N12: 0 | O12: 0 | P12: 2
A13: 8 | B13: 0 | C13: 0 | D13: 0 | E13: 0 | F13: 0 | G13: 0 | H13: 0 | I13: 0 | J13: 0 | K13: 0 | L13: 0 | M13: 0 | N13: 0 | O13: 0 | P13: 2
... A17: 12 | B17: 4 | C17: 4 | D17: 4 | E17: 4 | F17: 4 | G17: 4 | H17: 4 | I17: 4 | J17: 4 | K17: 4 | L17: 4 | M17: 4 | N17: 4 | O17: 4 | P17: 6
A19: +----+----+----+----+----+----+----+----+----+----+----+----+----+----+----+----+
A20: | 55 54 53 48| : : : : : : : : : : : |
A21: +----+----+----+ +....+....+....+....+....+....+....+....+....+....+....+....+
A22: | 4| 37 42 43| : : : : : : : : : : : |
A23: + + +----+ +....+....+....+....+....+....+....+....+....+....+....+....+
A24: | 5| 36| 35| 48: : : : : : : : : : : : |
A25: + + + +----+....+....+....+....+....+....+....+....+....+....+....+....+
A26: | 6| 31 30 25| : : : : : : : : : : : |
A27: + +----+----+ +....+....+....+....+....+....+....+....+....+....+....+....+
A28: | 7 12| 29 24| : : : : : : : : : : : |
A29: + +....+ + +....+....+....+....+....+....+....+....+....+....+....+....+
A30: | 8| | 34| 23| : : : : : : : : : : : |
... A225: +----+----+----+----+----+----+----+----+----+----+----+----+----+----+----+----+
A227: status | B227: X | C227: Y | D227: A | E227: S5 | F227: S4 | G227: S3 | H227: S2 | I227: S1 | J227: S0 | K227: S6 | L227: PWM_L PWM_R | M227: ENC_L ENC_C ENC_R | N227: G_sum | O227: G_sum_global
A229: 98 : 3 4 1 | B229: -416.66667 | C229: 52 | D229: 628 | E229: 864 | F229: 0 | G229: 192 | H229: 128 | I229: 316 | J229: -416.66667 | K229: 0 | L229: 64 | M229: -416.66667 | N229: 128 | O229: -64 | P229: -256 | Q229: -416.66667 | R229: 0 | S229: 0
A230: 71 : 0 8 33 | B230: -416.66667 | C230: 64 | D230: 240 | E230: 304 | F230: 260 | G230: 768 | H230: 640 | I230: 40 | J230: -416.66667 | K230: 0 | L230: 0 | M230: -416.66667 | N230: 0 | O230: 8 | P230: 16 | Q230: -416.66667 | R230: 0 | S230: 4
A231: 96 : 0 0 65 | B231: -416.66667 | C231: 540 | D231: 112 | E231: 512 | F231: 160 | G231: 128 | H231: 144 | I231: 172 | J231: -416.66667 | K231: 4 | L231: -64 | M231: -416.66667 | N231: -232 | O231: -44 | P231: 144 | Q231: -416.66667 | R231: 64 | S231: 0
A232: 99 : 0 8 33 | B232: -416.66667 | C232: 40 | D232: 80 | E232: 816 | F232: 272 | G232: 256 | H232: 96 | I232: 60 | J232: -416.66667 | K232: 10 | L232: 2 | M232: -416.66667 | N232: 64 | O232: 34 | P232: 4 | Q232: -416.66667 | R232: -256 | S232: 64
A233: 99 : 10 8 32 | B233: -416.66667 | C233: 316 | D233: 632 | E233: 8 | F233: 384 | G233: 288 | H233: 144 | I233: 40 | J233: -416.66667 | K233: 0 | L233: 68 | M233: -416.66667 | N233: 72 | O233: 46 | P233: 20 | Q233: -416.66667 | R233: -128 | S233: 66
A234: -82 : 2 0 27 | B234: -416.66667 | C234: 712 | D234: 356 | E234: 64 | F234: 256 | G234: 272 | H234: 400 | I234: 316 | J234: -416.66667 | K234: 42 | L234: -118 | M234: -416.66667 | N234: 4 | O234: 2 | P234: 0 | Q234: -416.66667 | R234: 16 | S234: 64
A235: 0 : 9 0 49 | B235: -416.66667 | C235: 60 | D235: 376 | E235: 128 | F235: 260 | G235: 512 | H235: 916 | I235: 264 | J235: -416.66667 | K235: 10 | L235: 74 | M235: -416.66667 | N235: 8 | O235: 9 | P235: 10 | Q235: -416.66667 | R235: -256 | S235: 0
A236: -50 : 0 0 69 | B236: -416.66667 | C236: 312 | D236: 124 | E236: 772 | F236: 512 | G236: 288 | H236: 0 | I236: 40 | J236: -416.66667 | K236: 10 | L236: 8 | M236: -416.66667 | N236: 0 | O236: 2 | P236: 4 | Q236: -416.66667 | R236: 0 | S236: 64
A237: 0 : 0 0 1 | B237: -416.66667 | C237: 60 | D237: 120 | E237: 0 | F237: 0 | G237: 0 | H237: 140 | I237: 44 | J237: -416.66667 | K237: 10 | L237: 10 | M237: -416.66667 | N237: 0 | O237: 0 | P237: 0 | Q237: -416.66667 | R237: 0 | S237: 0
A238: 0 : 0 0 1 | B238: -416.66667 | C238: 60 | D238: 120 | E238: 4 | F238: 0 | G238: 0 | H238: 140 | I238: 44 | J238: -416.66667 | K238: 10 | L238: 10 | M238: -416.66667 | N238: 0 | O238: 0 | P238: 0 | Q238: -416.66667 | R238: 0 | S238: 0
A239: 0 : 0 0 1 | B239: -416.66667 | C239: 60 | D239: 120 | E239: 4 | F239: 0 | G239: 0 | H239: 140 | I239: 48 | J239: -416.66667 | K239: 10 | L239: 10 | M239: -416.66667 | N239: 4 | O239: 4 | P239: 4 | Q239: -416.66667 | R239: 0 | S239: 0
A240: 0 : 0 0 1 | B240: -416.66667 | C240: 64 | D240: 120 | E240: 0 | F240: 0 | G240: 0 | H240: 140 | I240: 48 | J240: -416.66667 | K240: 10 | L240: 10 | M240: -416.66667 | N240: 6 | O240: 6 | P240: 6 | Q240: -416.66667 | R240: 0 | S240: 0
...

Sheet 経路
B1: L_ENC | D1: R_ENC | G1: ENCパルス数 | H1: x | I1: y | J1: angle
A2: =INDEX(ログ!A:A,$F$11+ROW(A1)-1) -> 0 : 0 0 1 | B2: =INDEX(ログ!N:N,$F$11+ROW(A1)-1)*$G$5 -> 0 | C2: =(B2+D2)/2 -> 0 | D2: =SUBSTITUTE(INDEX(ログ!P:P,$F$11+ROW(A1)-1),":","")*$G$5 -> 0 | G2: 400 | H2: =90+C2*COS(RADIANS(J2)) -> 90 | I2: =-90+C2*SIN(RADIANS(J2)) -> -90 | J2: =ROUNDDOWN(INDEX(ログ!S:S,$F$11+ROW(A1)-1) * $F$8,0) -> 0
A3: =INDEX(ログ!A:A,$F$11+ROW(A2)-1) -> 0 : 0 0 1 | B3: =INDEX(ログ!N:N,$F$11+ROW(A2)-1)*$G$5 -> 0 | C3: =(B3+D3)/2 -> 0 | D3: =SUBSTITUTE(INDEX(ログ!P:P,$F$11+ROW(A2)-1),":","")*$G$5 -> 0 | H3: =H2+(C3*COS(RADIANS(J2))) -> 90 | I3: =I2+(C3*SIN(RADIANS(J2))) -> -90 | J3: =ROUNDDOWN(INDEX(ログ!S:S,$F$11+ROW(A2)-1) * $F$8,0) -> 0
A4: =INDEX(ログ!A:A,$F$11+ROW(A3)-1) -> 0 : 0 0 1 | B4: =INDEX(ログ!N:N,$F$11+ROW(A3)-1)*$G$5 -> 0.69115038 | C4: =(B4+D4)/2 -> 0.69115038 | D4: =SUBSTITUTE(INDEX(ログ!P:P,$F$11+ROW(A3)-1),":","")*$G$5 -> 0.69115038 | F4: タイヤ直径 | G4: 1パルスあたり | H4: =H3+(C4*COS(RADIANS(J3))) -> 90.69115 | I4: =I3+(C4*SIN(RADIANS(J3))) -> -90 | J4: =ROUNDDOWN(INDEX(ログ!S:S,$F$11+ROW(A3)-1) * $F$8,0) -> 0
A5: =INDEX(ログ!A:A,$F$11+ROW(A4)-1) -> 0 : 0 0 1 | B5: =INDEX(ログ!N:N,$F$11+ROW(A4)-1)*$G$5 -> 1.0367256 | C5: =(B5+D5)/2 -> 1.0367256 | D5: =SUBSTITUTE(INDEX(ログ!P:P,$F$11+ROW(A4)-1),":","")*$G$5 -> 1.0367256 | F5: 22 | G5: =F5*PI()/G2 -> 0.1727876 | H5: =H4+(C5*COS(RADIANS(J4))) -> 91.727876 | I5: =I4+(C5*SIN(RADIANS(J4))) -> -90 | J5: =ROUNDDOWN(INDEX(ログ!S:S,$F$11+ROW(A4)-1) * $F$8,0) -> 0
A6: =INDEX(ログ!A:A,$F$11+ROW(A5)-1) -> 0 : 0 0 1 | B6: =INDEX(ログ!N:N,$F$11+ROW(A5)-1)*$G$5 -> 1.3823008 | C6: =(B6+D6)/2 -> 1.2095132 | D6: =SUBSTITUTE(INDEX(ログ!P:P,$F$11+ROW(A5)-1),":","")*$G$5 -> 1.0367256 | H6: =H5+(C6*COS(RADIANS(J5))) -> 92.937389 | I6: =I5+(C6*SIN(RADIANS(J5))) -> -90 | J6: =ROUNDDOWN(INDEX(ログ!S:S,$F$11+ROW(A5)-1) * $F$8,0) -> 0
A7: =INDEX(ログ!A:A,$F$11+ROW(A6)-1) -> 0 : 0 0 1 | B7: =INDEX(ログ!N:N,$F$11+ROW(A6)-1)*$G$5 -> 1.3823008 | C7: =(B7+D7)/2 -> 1.3823008 | D7: =SUBSTITUTE(INDEX(ログ!P:P,$F$11+ROW(A6)-1),":","")*$G$5 -> 1.3823008 | F7: ジャイロの微調整 | H7: =H6+(C7*COS(RADIANS(J6))) -> 94.31969 | I7: =I6+(C7*SIN(RADIANS(J6))) -> -90 | J7: =ROUNDDOWN(INDEX(ログ!S:S,$F$11+ROW(A6)-1) * $F$8,0) -> 0
A8: =INDEX(ログ!A:A,$F$11+ROW(A7)-1) -> 0 : 0 0 1 | B8: =INDEX(ログ!N:N,$F$11+ROW(A7)-1)*$G$5 -> 1.3823008 | C8: =(B8+D8)/2 -> 1.3823008 | D8: =SUBSTITUTE(INDEX(ログ!P:P,$F$11+ROW(A7)-1),":","")*$G$5 -> 1.3823008 | F8: 1 | H8: =H7+(C8*COS(RADIANS(J7))) -> 95.701991 | I8: =I7+(C8*SIN(RADIANS(J7))) -> -90 | J8: =ROUNDDOWN(INDEX(ログ!S:S,$F$11+ROW(A7)-1) * $F$8,0) -> 0
A9: =INDEX(ログ!A:A,$F$11+ROW(A8)-1) -> 0 : 0 0 1 | B9: =INDEX(ログ!N:N,$F$11+ROW(A8)-1)*$G$5 -> 1.727876 | C9: =(B9+D9)/2 -> 1.9006636 | D9: =SUBSTITUTE(INDEX(ログ!P:P,$F$11+ROW(A8)-1),":","")*$G$5 -> 2.0734512 | H9: =H8+(C9*COS(RADIANS(J8))) -> 97.602654 | I9: =I8+(C9*SIN(RADIANS(J8))) -> -90 | J9: =ROUNDDOWN(INDEX(ログ!S:S,$F$11+ROW(A8)-1) * $F$8,0) -> 0
A10: =INDEX(ログ!A:A,$F$11+ROW(A9)-1) -> 0 : 0 0 1 | B10: =INDEX(ログ!N:N,$F$11+ROW(A9)-1)*$G$5 -> 1.727876 | C10: =(B10+D10)/2 -> 1.9006636 | D10: =SUBSTITUTE(INDEX(ログ!P:P,$F$11+ROW(A9)-1),":","")*$G$5 -> 2.0734512 | F10: ログの開始位置 | G10: 終了位置 | H10: =H9+(C10*COS(RADIANS(J9))) -> 99.503318 | I10: =I9+(C10*SIN(RADIANS(J9))) -> -90 | J10: =ROUNDDOWN(INDEX(ログ!S:S,$F$11+ROW(A9)-1) * $F$8,0) -> 0
A11: =INDEX(ログ!A:A,$F$11+ROW(A10)-1) -> 0 : 0 0 1 | B11: =INDEX(ログ!N:N,$F$11+ROW(A10)-1)*$G$5 -> 2.0734512 | C11: =(B11+D11)/2 -> 2.0734512 | D11: =SUBSTITUTE(INDEX(ログ!P:P,$F$11+ROW(A10)-1),":","")*$G$5 -> 2.0734512 | F11: 237 | G11: 400 | H11: =H10+(C11*COS(RADIANS(J10))) -> 101.57677 | I11: =I10+(C11*SIN(RADIANS(J10))) -> -90 | J11: =ROUNDDOWN(INDEX(ログ!S:S,$F$11+ROW(A10)-1) * $F$8,0) -> 0
A12: =INDEX(ログ!A:A,$F$11+ROW(A11)-1) -> 0 : 0 0 1 | B12: =INDEX(ログ!N:N,$F$11+ROW(A11)-1)*$G$5 -> 2.0734512 | C12: =(B12+D12)/2 -> 2.2462387 | D12: =SUBSTITUTE(INDEX(ログ!P:P,$F$11+ROW(A11)-1),":","")*$G$5 -> 2.4190263 | F12: ↑ログシート | G12: ↑経路シート | H12: =H11+(C12*COS(RADIANS(J11))) -> 103.82301 | I12: =I11+(C12*SIN(RADIANS(J11))) -> -90 | J12: =ROUNDDOWN(INDEX(ログ!S:S,$F$11+ROW(A11)-1) * $F$8,0) -> 0
A13: =INDEX(ログ!A:A,$F$11+ROW(A12)-1) -> 0 : 0 0 1 | B13: =INDEX(ログ!N:N,$F$11+ROW(A12)-1)*$G$5 -> 2.4190263 | C13: =(B13+D13)/2 -> 2.4190263 | D13: =SUBSTITUTE(INDEX(ログ!P:P,$F$11+ROW(A12)-1),":","")*$G$5 -> 2.4190263 | H13: =H12+(C13*COS(RADIANS(J12))) -> 106.24203 | I13: =I12+(C13*SIN(RADIANS(J12))) -> -90 | J13: =ROUNDDOWN(INDEX(ログ!S:S,$F$11+ROW(A12)-1) * $F$8,0) -> 0
A14: =INDEX(ログ!A:A,$F$11+ROW(A13)-1) -> 0 : 0 0 1 | B14: =INDEX(ログ!N:N,$F$11+ROW(A13)-1)*$G$5 -> 2.4190263 | C14: =(B14+D14)/2 -> 2.4190263 | D14: =SUBSTITUTE(INDEX(ログ!P:P,$F$11+ROW(A13)-1),":","")*$G$5 -> 2.4190263 | H14: =H13+(C14*COS(RADIANS(J13))) -> 108.66106 | I14: =I13+(C14*SIN(RADIANS(J13))) -> -90 | J14: =ROUNDDOWN(INDEX(ログ!S:S,$F$11+ROW(A13)-1) * $F$8,0) -> 0
A15: =INDEX(ログ!A:A,$F$11+ROW(A14)-1) -> 0 : 0 0 1 | B15: =INDEX(ログ!N:N,$F$11+ROW(A14)-1)*$G$5 -> 2.4190263 | C15: =(B15+D15)/2 -> 2.5918139 | D15: =SUBSTITUTE(INDEX(ログ!P:P,$F$11+ROW(A14)-1),":","")*$G$5 -> 2.7646015 | H15: =H14+(C15*COS(RADIANS(J14))) -> 111.25287 | I15: =I14+(C15*SIN(RADIANS(J14))) -> -90 | J15: =ROUNDDOWN(INDEX(ログ!S:S,$F$11+ROW(A14)-1) * $F$8,0) -> 0
A16: =INDEX(ログ!A:A,$F$11+ROW(A15)-1) -> 0 : 0 0 1 | B16: =INDEX(ログ!N:N,$F$11+ROW(A15)-1)*$G$5 -> 2.7646015 | C16: =(B16+D16)/2 -> 2.9373891 | D16: =SUBSTITUTE(INDEX(ログ!P:P,$F$11+ROW(A15)-1),":","")*$G$5 -> 3.1101767 | H16: =H15+(C16*COS(RADIANS(J15))) -> 114.19026 | I16: =I15+(C16*SIN(RADIANS(J15))) -> -90 | J16: =ROUNDDOWN(INDEX(ログ!S:S,$F$11+ROW(A15)-1) * $F$8,0) -> 0
A17: =INDEX(ログ!A:A,$F$11+ROW(A16)-1) -> 0 : 0 0 1 | B17: =INDEX(ログ!N:N,$F$11+ROW(A16)-1)*$G$5 -> 3.1101767 | C17: =(B17+D17)/2 -> 2.9373891 | D17: =SUBSTITUTE(INDEX(ログ!P:P,$F$11+ROW(A16)-1),":","")*$G$5 -> 2.7646015 | H17: =H16+(C17*COS(RADIANS(J16))) -> 117.12765 | I17: =I16+(C17*SIN(RADIANS(J16))) -> -90 | J17: =ROUNDDOWN(INDEX(ログ!S:S,$F$11+ROW(A16)-1) * $F$8,0) -> 0
A18: =INDEX(ログ!A:A,$F$11+ROW(A17)-1) -> 0 : 0 0 1 | B18: =INDEX(ログ!N:N,$F$11+ROW(A17)-1)*$G$5 -> 3.4557519 | C18: =(B18+D18)/2 -> 3.4557519 | D18: =SUBSTITUTE(INDEX(ログ!P:P,$F$11+ROW(A17)-1),":","")*$G$5 -> 3.4557519 | H18: =H17+(C18*COS(RADIANS(J17))) -> 120.5834 | I18: =I17+(C18*SIN(RADIANS(J17))) -> -90 | J18: =ROUNDDOWN(INDEX(ログ!S:S,$F$11+ROW(A17)-1) * $F$8,0) -> 0
A19: =INDEX(ログ!A:A,$F$11+ROW(A18)-1) -> 0 : 0 0 1 | B19: =INDEX(ログ!N:N,$F$11+ROW(A18)-1)*$G$5 -> 3.4557519 | C19: =(B19+D19)/2 -> 3.6285395 | D19: =SUBSTITUTE(INDEX(ログ!P:P,$F$11+ROW(A18)-1),":","")*$G$5 -> 3.8013271 | H19: =H18+(C19*COS(RADIANS(J18))) -> 124.21194 | I19: =I18+(C19*SIN(RADIANS(J18))) -> -90 | J19: =ROUNDDOWN(INDEX(ログ!S:S,$F$11+ROW(A18)-1) * $F$8,0) -> 0
A20: =INDEX(ログ!A:A,$F$11+ROW(A19)-1) -> 0 : 0 0 1 | B20: =INDEX(ログ!N:N,$F$11+ROW(A19)-1)*$G$5 -> 4.1469023 | C20: =(B20+D20)/2 -> 4.1469023 | D20: =SUBSTITUTE(INDEX(ログ!P:P,$F$11+ROW(A19)-1),":","")*$G$5 -> 4.1469023 | H20: =H19+(C20*COS(RADIANS(J19))) -> 128.35885 | I20: =I19+(C20*SIN(RADIANS(J19))) -> -90 | J20: =ROUNDDOWN(INDEX(ログ!S:S,$F$11+ROW(A19)-1) * $F$8,0) -> 0
A21: =INDEX(ログ!A:A,$F$11+ROW(A20)-1) -> 0 : 0 0 1 | B21: =INDEX(ログ!N:N,$F$11+ROW(A20)-1)*$G$5 -> 4.4924775 | C21: =(B21+D21)/2 -> 4.6652651 | D21: =SUBSTITUTE(INDEX(ログ!P:P,$F$11+ROW(A20)-1),":","")*$G$5 -> 4.8380527 | H21: =H20+(C21*COS(RADIANS(J20))) -> 133.02411 | I21: =I20+(C21*SIN(RADIANS(J20))) -> -90 | J21: =ROUNDDOWN(INDEX(ログ!S:S,$F$11+ROW(A20)-1) * $F$8,0) -> 0
A22: =INDEX(ログ!A:A,$F$11+ROW(A21)-1) -> 0 : 0 0 1 | B22: =INDEX(ログ!N:N,$F$11+ROW(A21)-1)*$G$5 -> 4.8380527 | C22: =(B22+D22)/2 -> 5.0108403 | D22: =SUBSTITUTE(INDEX(ログ!P:P,$F$11+ROW(A21)-1),":","")*$G$5 -> 5.1836279 | H22: =H21+(C22*COS(RADIANS(J21))) -> 138.03495 | I22: =I21+(C22*SIN(RADIANS(J21))) -> -90 | J22: =ROUNDDOWN(INDEX(ログ!S:S,$F$11+ROW(A21)-1) * $F$8,0) -> 0
A23: =INDEX(ログ!A:A,$F$11+ROW(A22)-1) -> 0 : 0 0 1 | B23: =INDEX(ログ!N:N,$F$11+ROW(A22)-1)*$G$5 -> 5.8747783 | C23: =(B23+D23)/2 -> 6.0475659 | D23: =SUBSTITUTE(INDEX(ログ!P:P,$F$11+ROW(A22)-1),":","")*$G$5 -> 6.2203535 | H23: =H22+(C23*COS(RADIANS(J22))) -> 144.08252 | I23: =I22+(C23*SIN(RADIANS(J22))) -> -90 | J23: =ROUNDDOWN(INDEX(ログ!S:S,$F$11+ROW(A22)-1) * $F$8,0) -> 0
A24: =INDEX(ログ!A:A,$F$11+ROW(A23)-1) -> 0 : 0 0 1 | B24: =INDEX(ログ!N:N,$F$11+ROW(A23)-1)*$G$5 -> 6.9115038 | C24: =(B24+D24)/2 -> 6.7387162 | D24: =SUBSTITUTE(INDEX(ログ!P:P,$F$11+ROW(A23)-1),":","")*$G$5 -> 6.5659286 | H24: =H23+(C24*COS(RADIANS(J23))) -> 150.82123 | I24: =I23+(C24*SIN(RADIANS(J23))) -> -90 | J24: =ROUNDDOWN(INDEX(ログ!S:S,$F$11+ROW(A23)-1) * $F$8,0) -> 0
... A669: =INDEX(ログ!A:A,$F$11+ROW(A668)-1) -> 0 | B669: =INDEX(ログ!N:N,$F$11+ROW(A668)-1)*$G$5 -> 0 | C669: =(B669+D669)/2 -> #VALUE! | D669: =SUBSTITUTE(INDEX(ログ!P:P,$F$11+ROW(A668)-1),":","")*$G$5 -> #VALUE! | H669: =H668+(C669*COS(RADIANS(J668))) -> #VALUE! | I669: =I668+(C669*SIN(RADIANS(J668))) -> #VALUE! | J669: =ROUNDDOWN(INDEX(ログ!S:S,$F$11+ROW(A668)-1) * $F$8,0) -> 0
